Workbook
Name ACTION: #REF!
Name ACTION: #REF!

Sheet Cover
B2: TEST REPORT DOCUMENT
A4: Project Name | B4: Learner Management and 3D Simulation System for Crane Training Center (LSSCTC) | E4: Creator | F4: Dao Trong Duc, Le Nhat Quang
A5: Project Code | B5: LSSCTC | E5: Issue Date | F5: 45992
A6: Document Code | B6: =B5&"_"&"XXX"&"_"&"vx.x" -> LSSCTC_XXX_vx.x | E6: Version | F6: 1
A9: Record of change
A10: Effective Date | B10: Version | C10: Change Item | D10: *A,D,M | E10: Change description | F10: Reference
A11: <Date when these changes are effective> | F11: <List of documents which are refered in this version.>

Sheet Test Cases
D1: TEST CASE LIST
B3: Project Name | D3: Learner Management and 3D Simulation System for Crane Training Center (LSSCTC)
B4: Project Code | D4: =#REF! -> #REF!
B5: Test Environment Setup Description | D5: <List enviroment requires in this system 1. Server 2. Database 3. Web Browser ... >
B8: No | C8: Function Name | D8: Sheet Name | E8: Description | F8: Pre-Condition
B9: 1 | C9: Training Content & Curriculum Management | D9: Feature1 | E9: Create/Edit Programs, Courses, Classes, Sections, and Materials | F9: Admin or Instructor logged in
B10: 2 | C10: Trainee Enrollment & Learning Process | D10: Feature2 | E10: Trainee enrollment, accessing My Classes, and viewing learning content | F10: Trainee logged in with valid account
B11: 3 | C11: Simulation Integration & Practice Session | D11: Feature3 | E11: Launch simulation from Web, handshake auth, and sync results back to Web | F11: Sim Client installed & Session active
B12: 4 | C12: Trainee Final Exam Module | D12: Feature4 | E12: Trainee taking Theory and Simulation exams with timer and validation | F12: Exam scheduled & Open Code valid
B13: 5 | C13: System Dashboard & Analytics | D13: Feature5 | E13: View statistics and charts for Admin, Instructor, and Sim Manager | F13: User logged in with appropriate role

Sheet Test Statistics
B1: TEST STATISTICS
B3: Project Name | C3: <Project Name> | E3: Creator
B4: Project Code | C4: <Project Code> | E4: Reviewer/Approver
B5: Document Code | C5: =C4&"_"&"Test Report"&"_"&"vx.x" -> <Project Code>_Test Report_vx.x | E5: Issue Date | H5: <Date when this test report is created>
B6: Notes | C6: <List modules included in this release> ex: Release 1 includes 2 modules: Module1 and Module2
B10: No | C10: Module code | D10: Passed | E10: Failed | F10: Pending | G10: N/A | H10: Number of test cases
B11: 1 | C11: ='Feature 1'!B2 -> Training Content & Curriculum Management | D11: ='Feature 1'!B6 -> 50 | E11: ='Feature 1'!C6 -> 0 | F11: ='Feature 1'!D6 -> 0 | G11: ='Feature 1'!E6 -> 0 | H11: ='Feature 1'!B4 -> 56
B12: 2 | C12: ='Feature 2'!B2 -> Trainee Enrollment & Learning Process | D12: ='Feature 2'!B6 -> 73 | E12: ='Feature 2'!C6 -> 0 | F12: ='Feature 2'!D6 -> 0 | G12: ='Feature 2'!E6 -> 0 | H12: ='Feature 2'!B4 -> 73
B13: 3 | C13: ='Feature 3'!B2 -> Simulation Integration & Practice Session | D13: ='Feature 3'!B6 -> 9 | E13: ='Feature 3'!C6 -> 0 | F13: ='Feature 3'!D6 -> 0 | G13: ='Feature 3'!E6 -> 0 | H13: ='Feature 3'!B4 -> 9
B14: 4 | C14: ='Feature 4'!B2 -> Trainee Final Exam Module | D14: ='Feature 4'!B6 -> 36 | E14: ='Feature 4'!C6 -> 0 | F14: ='Feature 4'!D6 -> 0 | G14: ='Feature 4'!E6 -> 0 | H14: ='Feature 4'!B4 -> 36
B15: 5 | C15: ='Feature 5'!B2 -> Dashboard management | D15: ='Feature 5'!B6 -> 23 | E15: ='Feature 4'!C6 -> 0 | F15: ='Feature 5'!D6 -> 0 | G15: ='Feature 5'!E6 -> 0 | H15: ='Feature 5'!B4 -> 23
C16: Sub total | D16: =SUM(D9:D15) -> 191 | E16: =SUM(E9:E15) -> 0 | F16: =SUM(F9:F15) -> 0 | G16: =SUM(G9:G15) -> 0 | H16: =SUM(H9:H15) -> 197
C18: Test coverage | E18: =(D16+E16)*100/(H16-G16) -> 96.954315 | F18: %
C19: Test successful coverage | E19: =D16*100/(H16-G16) -> 96.954315 | F19: %

Sheet Feature 1
A2: Feature | B2: Training Content & Curriculum Management | R2: Passed
A3: Test requirement | B3: Verify the end-to-end training content creation workflow. Ensure Administrators can create and configure Training Programs, Courses, and Classes. Ensure Instructors can manage Course Sections, upload Learning Materials, and create Quizzes. Verify that all created content is correctly linked and displayed for Trainee enrollment. | R3: Failed
A4: Number of TCs | B4: =COUNTA(A12:A1022) -> 56 | R4: Pending
A5: Testing Round | B5: Passed | C5: Failed | D5: Pending | E5: N/A | R5: N/A
A6: Round 1 | B6: =COUNTIF($F10:$F1020,B5) -> 50 | C6: =COUNTIF($F10:$F1020,C5) -> 0 | D6: =COUNTIF($F10:$F1020,D5) -> 0 | E6: =COUNTIF($F10:$F1020,E5) -> 0
A7: Round 2 | B7: =COUNTIF($I10:$I1020,B5) -> 0 | C7: =COUNTIF($I10:$I1020,C5) -> 0 | D7: =COUNTIF($I10:$I1020,D5) -> 0 | E7: =COUNTIF($I10:$I1020,E5) -> 0
A8: Round 3 | B8: =COUNTIF($L10:$L1020,B5) -> 0 | C8: =COUNTIF($L10:$L1020,C5) -> 0 | D8: =COUNTIF($L10:$L1020,D5) -> 0 | E8: =COUNTIF($L10:$L1020,E5) -> 0
A10: Test Case ID | B10: Test Case Description | C10: Test Case Procedure | D10: Expected Results | E10: Pre-conditions | F10: Round 1 | G10: Test date | H10: Tester | I10: Round 2 | J10: Test date | K10: Tester | L10: Round 3 | M10: Test date | N10: Tester | O10: Note
A11: Program Manager
A12: TC_PROG_001 | B12: Verify Create Program UI | C12: 1. Log in as Admin.2. Navigate to Program Management.3. Click "Create Program". | D12: 1. Name input (Placeholder: Enter program name).2. Image URL input.3. Description textarea.4. Image Preview box visible.5. Buttons visible. | E12: Admin logged in | F12: Passed
A13: TC_PROG_002 | B13: Create Program with Valid Data | C13: 1. Enter valid Name.2. Enter Image URL.3. Enter Description.4. Click Create. | D13: 1. No validation errors.2. Spinner appears.3. Form submits successfully. | E13: Form is open | F13: Passed
A14: TC_PROG_003 | B14: Validate Required Fields Program | C14: 1. Leave Name, Image, Desc empty.2. Click Create. | D14: 1. Error messages appear under required fields (Name, Description). | E14: Form is open | F14: Passed
A15: TC_PROG_004 | B15: Validate Image URL Format | C15: 1. Enter invalid text in URL field.2. Submit. | D15: 1. Error message: "Must be a valid URL".2. Submit blocked. | E15: Form is open | F15: Passed
A16: TC_PROG_005 | B16: Verify Image Preview | C16: 1. Enter valid image URL.2. Blur input. | D16: 1. Preview box shows the image correctly. | E16: Form is open | F16: Passed
A17: Course Manager
A18: TC_CS_001 | B18: Verify Create Course UI | C18: 1. Navigate to Courses.2. Click "Create Course". | D18: 1. All fields present (Name, Code, Price, Duration, etc). | E18: Admin logged in | F18: Passed
A19: TC_CS_002 | B19: Create Course Success | C19: 1. Fill Name, Code, Price, Duration.2. Click "Add Course". | D19: 1. Success message appears.2. Course added to list. | E19: Form is open | F19: Passed
A20: TC_CS_003 | B20: Validate Course Required Fields | C20: 1. Leave all empty.2. Click Add. | D20: 1. Error messages for Name, Code, Price, Duration. | E20: Form is open | F20: Passed
A21: TC_CS_004 | B21: Validate Course Price Range | C21: 1. Enter Price: -1.2. Click Add. | D21: 1. Error: Price must be >= 0. | E21: Form is open | F21: Passed
A22: TC_CS_005 | B22: Validate Duration Range | C22: 1. Enter Duration: 10000.2. Click Add. | D22: 1. Error: Duration invalid (too high). | E22: Form is open | F22: Passed
A23: Assign Course
A24: TC_ASSIGN_01 | B24: Verify Assign Course UI | C24: 1. Open Program.2. Click "Add Course". | D24: 1. Modal "Assign Course" appears.2. Course dropdown visible. | E24: Program Detail | F24: Passed
A25: TC_ASSIGN_02 | B25: Assign Course Success | C25: 1. Select unassigned course.2. Click Save. | D25: 1. Success message.2. Course listed in program. | E25: Modal open | F25: Passed
A26: TC_ASSIGN_03 | B26: Validate Empty Selection | C26: 1. Don't select course.2. Click Save. | D26: 1. Error: "Please select a course". | E26: Modal open | F26: Passed
A27: TC_ASSIGN_04 | B27: Assign Duplicate Course | C27: 1. Select course already in program.2. Click Save. | D27: 1. Error message: "Course already assigned". | E27: Modal open | F27: Passed
A28: Manage Classes (Create Class)
A29: TC_CLS_001 | B29: Verify Create Class UI | C29: 1. Go to Class Mgmt.2. Click "Add Class". | D29: 1. Check Inputs: Code, Name, Dates, Schedule. | E29: Admin logged in | F29: Passed
A30: TC_CLS_002 | B30: Create Class Success | C30: 1. Fill valid data.2. Set valid Schedule.3. Click Save. | D30: 1. Success message.2. Class visible in list. | E30: Form open | F30: Passed
A31: TC_CLS_003 | B31: Validate Duplicate Class Code | C31: 1. Enter existing Code.2. Save. | D31: 1. Error message from API: "Code exists". | E31: Form open | F31: Passed
A32: TC_CLS_004 | B32: Validate Max Trainees Logic | C32: 1. Enter Max Trainees: 0 or 1000.2. Save. | D32: 1. Error: Value out of range. | E32: Form open | F32: Passed
A33: Assign Instructor to Class
A34: TC_INS_001 | B34: Verify Instructor Dropdown | C34: 1. Click on "Instructor" dropdown. | D34: 1. List of instructors loaded. | E34: Form open | F34: Passed
A35: TC_INS_002 | B35: Assign Instructor Success | C35: 1. Select valid Instructor.2. Save Class. | D35: 1. Class created with assigned instructor. | E35: Form open | F35: Passed
A36: TC_INS_003 | B36: Remove/Change Instructor | C36: 1. Edit Class.2. Change Instructor value.3. Save. | D36: 1. Class instructor updated. | E36: Class exists | F36: Passed
F37: Passed
A38: Add Timeslot (Class Schedule) | F38: Passed
A39: TC_SCH_001 | B39: Verify Schedule Inputs | C39: 1. Scroll to Schedule section. | D39: 1. Date pickers & Time pickers visible.2. Days of week visible. | E39: Form open | F39: Passed
A40: TC_SCH_002 | B40: Validate End Date < Start | C40: 1. Set End Date before Start Date. | D40: 1. System clears date OR shows error. | E40: Form open | F40: Passed
A41: TC_SCH_003 | B41: Validate Time Logic | C41: 1. Set End Time before Start Time. | D41: 1. Error: End time must be after start time. | E41: Form open | F41: Passed
A42: TC_SCH_004 | B42: Create Schedule Success | C42: 1. Pick valid Mon/Wed/Fri range.2. Save. | D42: 1. Slots generated correctly. | E42: Form open | F42: Passed
...

Sheet Feature 2
A2: Feature | B2: Trainee Enrollment & Learning Process | R2: Passed
A3: Test requirement | B3: Verify the end-to-end workflow for Trainee class enrollment and learning activities. Ensure Trainees can browse available classes, perform enrollment actions, and verify their enrollment status. Verify that enrolled Trainees can access 'My Classes', view the class schedule, access all learning materials (Sections, Documents, Videos), and correctly track their learning progress throughout the course. | R3: Failed
A4: Number of TCs | B4: =COUNTA(A12:A914) -> 73 | R4: Pending
A5: Testing Round | B5: Passed | C5: Failed | D5: Pending | E5: N/A | R5: N/A
A6: Round 1 | B6: =COUNTIF($F10:$F912,B5) -> 73 | C6: =COUNTIF($F10:$F912,C5) -> 0 | D6: =COUNTIF($F10:$F912,D5) -> 0 | E6: =COUNTIF($F10:$F912,E5) -> 0
A7: Round 2 | B7: =COUNTIF($I10:$I912,B5) -> 0 | C7: =COUNTIF($I10:$I912,C5) -> 0 | D7: =COUNTIF($I10:$I912,D5) -> 0 | E7: =COUNTIF($I10:$I912,E5) -> 0
A8: Round 3 | B8: =COUNTIF($L10:$L912,B5) -> 0 | C8: =COUNTIF($L10:$L912,C5) -> 0 | D8: =COUNTIF($L10:$L912,D5) -> 0 | E8: =COUNTIF($L10:$L912,E5) -> 0
A10: Test Case ID | B10: Test Case Description | C10: Test Case Procedure | D10: Expected Results | E10: Pre-conditions | F10: Round 1 | G10: Test date | H10: Tester | I10: Round 2 | J10: Test date | K10: Tester | L10: Round 3 | M10: Test date | N10: Tester | O10: Note
A11: Assign Trainee to Class
A12: TC_CLASS_ASSIGN_01 | B12: Verify Add Trainee Modal UI | C12: 1. Click the "Add Trainee" button. 2. Observe the modal. | D12: 1. Modal title is "Add Trainee". 2. A list of trainees is displayed (Name, Email, Phone). 3. Search bar and checkboxes are visible. 4. "Cancel" and "Add" buttons are present. | E12: 1. Admin is logged in. 2. A Class exists. 3. Admin is on "Class Detail" page. | F12: Passed
A13: TC_CLASS_ASSIGN_02 | B13: Add Single Trainee Successfully | C13: 1. Select (tick) 1 trainee. 2. Click "Add". | D13: 1. Modal closes. 2. Success toast message appears. 3. The selected trainee is added to the class list. | E13: 1. Admin is on "Class Detail" page. 2. "Add Trainee" modal is open. 3. At least 1 trainee exists. | F13: Passed
A14: TC_CLASS_ASSIGN_03 | B14: Add Multiple Trainees Successfully | C14: 1. Select multiple trainees (e.g., 3 trainees). 2. Click "Add". | D14: 1. Modal closes. 2. Success message: "Trainees added successfully". 3. All selected trainees appear in the list. | E14: 1. Admin is on "Class Detail" page. 2. "Add Trainee" modal is open. 3. Multiple trainees exist. | F14: Passed
A15: TC_CLASS_ASSIGN_04 | B15: Validate Empty Selection | C15: 1. Do not select any trainee. 2. Click "Add". | D15: 1. System does not proceed. 2. The "Add" button is disabled OR a warning message appears ("Please select at least one trainee"). | E15: 1. Admin is on "Class Detail" page. 2. "Add Trainee" modal is open. | F15: Passed
A16: TC_CLASS_ASSIGN_05 | B16: Close Modal without Adding | C16: 1. Select a trainee (optional). 2. Click "Cancel" or the "X" close button. | D16: 1. Modal closes. 2. No trainee is added to the class. | E16: 1. Admin is on "Class Detail" page. 2. "Add Trainee" modal is open. | F16: Passed
A17: Trainee Confirm Enrollment | F17: Passed
A18: TC_ENROLL_01 | B18: Verify "Confirm Enrollment" modal display | C18: 1. Login as a Trainee.2. Navigate to Course Detail page.3. Locate a class with Status "OPEN".4. Click the "Enroll" button on the class card. | D18: 1. "Confirm Enrollment" modal appears.2. Modal displays correctly:- Header: "Confirm Enrollment"- Class Name & Class Code (e.g., TestNo1)- Dates: Start Date, End Date- Status tag (OPEN)- Note text- Buttons: "Cancel", "Enroll Now" | E18: User is on the Course Detail page. At least one class is available for enrollment. | F18: Passed
A19: TC_ENROLL_02 | B19: Verify Class Information accuracy in Modal | C19: 1. Note the Class Code and Dates on the class card (outside modal).2. Click "Enroll" button on that specific card.3. Compare information in Modal with the card. | D19: information in the modal (Class Name, Code, Start Date, End Date) MUST match exactly with the selected class card. | E19: same as above | F19: Passed
A20: TC_ENROLL_03 | B20: Enroll successfully (Positive Case) | C20: 1. Open "Confirm Enrollment" modal.2. Click "Enroll Now" button.3. Wait for system response. | D20: 1. Loading state may appear briefly.2. Success message is displayed (e.g., "Enrolled successfully").3. Modal closes.4. Button on the class card changes status (e.g., to "Pending" or "Enrolled"). | E20: User is not yet enrolled in this class. | F20: Passed
A21: TC_ENROLL_04 | B21: Cancel enrollment via "Cancel" button | C21: 1. Open "Confirm Enrollment" modal.2. Click "Cancel" white button. | D21: 1. Modal closes immediately.2. User remains on the Course Page.3. No enrollment request is sent. | E21: Modal is open. | F21: Passed
A22: TC_ENROLL_05 | B22: Cancel enrollment via "X" (Close) icon | C22: 1. Open "Confirm Enrollment" modal.2. Click the "X" icon at the top-right corner of the modal. | D22: 1. Modal closes immediately.2. User remains on the Course Page. | E22: Modal is open. | F22: Passed
A23: TC_ENROLL_06 | B23: Verify UI responsiveness (Hover effects) | C23: 1. Hover mouse over "Cancel" button.2. Hover mouse over "Enroll Now" button. | D23: 1. "Cancel" button should show hover effect (e.g., gray background).2. "Enroll Now" button should show hover effect (e.g., darker blue). | E23: Modal is open. | F23: Passed
A24: TC_ENROLL_07 | B24: Handle API Error during Enrollment (Negative) | C24: 1. Open "Confirm Enrollment" modal.2. Disconnect internet OR simulate server error.3. Click "Enroll Now". | D24: 1. Error message is displayed (e.g., "Registration failed, please try again").2. Modal remains open or closes depending on logic (usually stays to retry). | E24: Modal is open. | F24: Passed
A25: Admin Confirm Trainee Enrollment | F25: Passed
A26: TC_ADM_CONFIRM_01 | B26: Verify "Pending" status display | C26: 1. Login as Admin.2. Navigate to Class Detail page of a class having pending enrollments.3. Scroll down to "Members" table section.4. Observe the user with "Pending" status tag. | D26: 1. The member row is displayed.2. Status column shows a yellow tag "Pending".3. Action column shows two icons: Check (Approve) and X (Reject). | E26: A trainee has enrolled in the class but not yet approved. | F26: Passed
A27: TC_ADM_CONFIRM_02 | B27: Approve Request successfully | C27: 1. In the Members table, locate a user with "Pending" status.2. Click the blue Check (✓) icon.3. Confirm the action if a popup appears. | D27: 1. A success message appears (e.g., "Trainee approved successfully").2. The status tag changes from "Pending" to "Enrolled" (or "Active").3. The Action icons (Check/X) disappear or change to other management actions (like remove). | E27: Trainee status is pending. | F27: Passed
A28: TC_ADM_CONFIRM_03 | B28: Reject Request successfully | C28: 1. In the Members table, locate a user with "Pending" status.2. Click the red X icon.3. Confirm the action in the confirmation popup. | D28: 1. A success message appears (e.g., "Trainee rejected successfully").2. The trainee is removed from the list OR status changes to "Rejected".3. The seat count (Capacity) remains unchanged or updates accordingly. | E28: Trainee status is pending. | F28: Passed
A29: TC_ADM_CONFIRM_04 | B29: Cancel Rejection Action | C29: 1. Click the red X icon for a pending trainee.2. In the confirmation popup, click "Cancel". | D29: 1. The popup closes.2. The trainee's status remains "Pending".3. No changes are applied. | E29: Trainee status is pending. | F29: Passed
A30: TC_ADM_CONFIRM_05 | B30: Verify Pagination with Pending Users | C30: 1. Ensure there are many pending requests (more than page size, e.g., > 10).2. Navigate to the next page of the members list.3. Approve a user on page 2. | D30: 1. User is approved.2. Admin remains on page 2 (or returns to page 1 if list becomes empty, depending on logic).3. Pagination updates correctly. | E30: 11+ pending trainees exist. | F30: Passed
A31: TC_ADM_CONFIRM_06 | B31: Approve User when Class is Full (Edge Case) | C31: 1. Ensure the class capacity is full (e.g., 10/10 enrolled).2. Try to approve another "Pending" trainee provided the system allowed over-requesting. | D31: 1. System validates capacity.2. An error message appears (e.g., "Class is full, cannot approve more trainees").3. User status remains "Pending". | E31: Class is full. 1 Pending request exists. | F31: Passed
A32: My Class Detail | F32: Passed
A33: TC_LEARN_TAB_01 | B33: Verify Learning Tab structure | C33: 1. Access "My Classes" list.2. Select a class marked "IN PROGRESS".3. Verify the "Học tập" (Learning) tab is active by default. | D33: 1. "Học tập" tab is highlighted.2. List of Chapters/Sections is displayed (marked 1, 2, 3...).3. Right side shows "Giảng viên" info and "Lịch học" (Schedule). | E33: Trainee is enrolled in at least one active class. | F33: Passed
A34: TC_LEARN_TAB_02 | B34: Verify Section Progress display | C34: 1. Observe the progress bar under each Section item (e.g., Section 1).2. Compare with the known progress (e.g., new class = 0%). | D34: 1. Progress bar shows correct percentage (e.g., 0%).2. Duration (e.g., "60 phút") is displayed correctly. | E34: Class has content. | F34: Passed
A35: TC_LEARN_NAV_01 | B35: Navigate to Learning Interface | C35: 1. Click on a Section item (e.g., "1"). | D35: 1. System redirects to the Learning Interface URL (e.g., /learnings/... ).2. The clicked section is automatically expanded in the sidebar. | E35: - | F35: Passed
A36: (Learning Interface) & Logic Session | F36: Passed
A37: TC_LEARN_UI_01 | B37: Verify Sidebar & Content Area | C37: 1. Access the Learning Interface.2. Observe layout. | D37: 1. Left Sidebar: Shows Chapters, Lessons (Video 1, PDF 1...).2. Main Area: Displays content of the selected lesson.3. Progress Header: Shows "Tiến độ của bạn" (e.g., 0/7 Hoạt động). | E37: - | F37: Passed
A38: TC_LEARN_SESSION_01 | B38: Verify "Session not started" Warning (Logic Check) | C38: 1. Navigate to a lesson where the scheduled Start Time is in the future (e.g., Start: 10/02/2026).2. Observe the main content area. | D38: 1. A yellow warning banner appears: "Phiên học chưa bắt đầu".2. Start and End times are displayed clearly.3. Content (Video/Exam) might be visible but functions (like "Mark as Complete") should be restricted. | E38: Lesson schedule is set to a future date. | F38: Passed
A39: TC_LEARN_SESSION_02 | B39: Attempt to complete locked session | C39: 1. Open a lesson with "Session not started" warning.2. Try to click "Mark as Complete" or Submit button (if available). | D39: 1. System shows an alert/error: "Session is not open" (or Vietnamese equivalent).2. Progress does NOT update. | E39: Session is closed/not started. | F39: Passed
A40: TC_LEARN_VIDEO_01 | B40: Verify Video Content Playback | C40: 1. Select a Video lesson (within an open session).2. Verify the video player loads. | D40: 1. Video player appears (YouTube/Uploaded file).2. Video title matches the sidebar name.3. Video can be played/paused. | E40: Session is OPEN. | F40: Passed
A41: TC_LEARN_PDF_01 | B41: Verify PDF/Document Content | C41: 1. Select a PDF or Document lesson.2. Verify the viewer loads. | D41: 1. Document viewer appears.2. Document content is readable. | E41: Session is OPEN. | F41: Passed
A42: TC_LEARN_PROG_01 | B42: Verify Progress Update | C42: 1. Complete a lesson (e.g., watch video and click "Mark as Complete").2. Observe the sidebar checklist and progress bar. | D42: 1. Checkmark appears next to the lesson in Sidebar.2. "Tiến độ của bạn" increases (e.g., from 0/7 to 1/7).3. Progress bar updates percentage. | E42: Session is OPEN. | F42: Passed
...

Sheet Feature 3
A2: Feature | B2: Simulation Integration & Practice Session | R2: Passed
A3: Test requirement | B3: Verify the integration mechanism between the Web Application and the 3D Simulation Client. Ensure that the 'Start Practice' action correctly triggers the external application with valid authentication tokens (Deep Linking/Handshake). Verify that practice results (Score, Duration, Completion Status) are successfully synchronized from the Simulator back to the Web App database upon session termination. | R3: Failed
A4: Number of TCs | B4: =COUNTA(A11:A994) -> 9 | R4: Pending
A5: Testing Round | B5: Passed | C5: Failed | D5: Pending | E5: N/A | R5: N/A
A6: Round 1 | B6: =COUNTIF($F10:$F992,B5) -> 9 | C6: =COUNTIF($F10:$F992,C5) -> 0 | D6: =COUNTIF($F10:$F992,D5) -> 0 | E6: =COUNTIF($F10:$F992,E5) -> 0
A7: Round 2 | B7: =COUNTIF($I10:$I992,B5) -> 0 | C7: =COUNTIF($I10:$I992,C5) -> 0 | D7: =COUNTIF($I10:$I992,D5) -> 0 | E7: =COUNTIF($I10:$I992,E5) -> 0
A8: Round 3 | B8: =COUNTIF($L10:$L992,B5) -> 0 | C8: =COUNTIF($L10:$L992,C5) -> 0 | D8: =COUNTIF($L10:$L992,D5) -> 0 | E8: =COUNTIF($L10:$L992,E5) -> 0
A10: Test Case ID | B10: Test Case Description | C10: Test Case Procedure | D10: Expected Results | E10: Pre-conditions | F10: Round 1 | G10: Test date | H10: Tester | I10: Round 2 | J10: Test date | K10: Tester | L10: Round 3 | M10: Test date | N10: Tester | O10: Note
A11: TC_SIM_WEB_01 | B11: Verify Simulator Launch Button | C11: 1. Login as Trainee.2. Navigate to a Practice Lesson.3. Locate action button. | D11: 1. "Start Practice" (Start Simulation) button is visible.2. Button is distinct (e.g., Primary color). | E11: Session Open. | F11: Passed
A12: TC_SIM_WEB_02 | B12: Launch Simulator (Redirect) | C12: 1. Click "Start Practice". | D12: 1. Redirects to Simulation Page OR triggers App Launch.2. No 404/Page Not Found error. | E12: - | F12: Passed
A13: TC_SIM_WEB_03 | B13: Check Session Status on Launch | C13: 1. Attempt launch when Session is Closed/Future. | D13: 1. Warning banner displayed.2. Launch action is restricted OR warning given about "No Scoring". | E13: Session Closed. | F13: Passed
A14: TC_SIM_WEB_04 | B14: Verify Identity Handshake | C14: 1. Launch Simulator.2. Check URL/Payload. | D14: 1. User ID / Token is passed correctly to initialize the simulation session. | E14: - | F14: Passed
A15: TC_SIM_WEB_05 | B15: Sync Completion Status | C15: 1. Finish practice in Simulator.2. Refresh Web Page. | D15: 1. Status updates to "Completed".2. Success indicators (Badge/Icon) appear. | E15: Sim Sync Success. | F15: Passed
A16: TC_SIM_WEB_06 | B16: Display Scores from Simulator | C16: 1. Finish with varying scores.2. View Web Details. | D16: 1. Task list reflects actual scores/Pass-Fail status from Simulator.2. Average calculations update. | E16: - | F16: Passed
A17: TC_SIM_WEB_07 | B17: Display Attempt History | C17: 1. Navigate to Practice Details.2. Look for log/history. | D17: 1. List of attempts/steps from Simulator is visible. | E17: - | F17: Passed
A18: TC_SIM_WEB_08 | B18: Handle Incomplete Attempts | C18: 1. Exit Simulator early.2. Check Web Status. | D18: 1. Status remains "In Progress".2. Re-launch allowed. | E18: - | F18: Passed
A19: TC_SIM_WEB_09 | B19: Validate Max Attempts | C19: 1. Reach max allowed attempts.2. Check Launch Button. | D19: 1. Button disabled OR text changes to "Review Mode". | E19: Limit reached. | F19: Passed

Sheet Feature 4
A2: Feature | B2: Trainee Final Exam Module | R2: Passed
A3: Test requirement | B3: Verify the complete workflow for accessing exam details, validating open codes, taking exams (Theory/Simulation), and viewing results for all exam types. | R3: Failed
A4: Number of TCs | B4: =COUNTA(A11:A995) -> 36 | R4: Pending
A5: Testing Round | B5: Passed | C5: Failed | D5: Pending | E5: N/A | R5: N/A
A6: Round 1 | B6: =COUNTIF($F10:$F993,B5) -> 36 | C6: =COUNTIF($F10:$F993,C5) -> 0 | D6: =COUNTIF($F10:$F993,D5) -> 0 | E6: =COUNTIF($F10:$F993,E5) -> 0
A7: Round 2 | B7: =COUNTIF($I10:$I993,B5) -> 0 | C7: =COUNTIF($I10:$I993,C5) -> 0 | D7: =COUNTIF($I10:$I993,D5) -> 0 | E7: =COUNTIF($I10:$I993,E5) -> 0
A8: Round 3 | B8: =COUNTIF($L10:$L993,B5) -> 0 | C8: =COUNTIF($L10:$L993,C5) -> 0 | D8: =COUNTIF($L10:$L993,D5) -> 0 | E8: =COUNTIF($L10:$L993,E5) -> 0
A10: Test Case ID | B10: Test Case Description | C10: Test Case Procedure | D10: Expected Results | E10: Pre-conditions | F10: Round 1 | G10: Test date | H10: Tester | I10: Round 2 | J10: Test date | K10: Tester | L10: Round 3 | M10: Test date | N10: Tester | O10: Note
A11: Test Case Specifications: Trainee Final Exam (Theory) | F11: Passed
A12: TC_EXAM_01 | B12: View Exam Info Successfully (Happy Case) | C12: 1. Navigate to Final Exam page.2. Wait for loading. | D12: 1. Exam Name, Description, Duration, Weight are displayed.2. Instructions are listed.3. Status shows "Not Started". | E12: Exam exists. | F12: Passed
A13: TC_EXAM_02 | B13: Start Exam with Valid Code (Happy Case) | C13: 1. Enter correct code in "Open Code" input.2. Click "Start Exam". | D13: 1. System verifies code.2. Redirects to "Exam Taking" page.3. Timer starts immediately. | E13: Valid Open Code. | F13: Passed
A14: TC_EXAM_03 | B14: Timer Countdown Normal (Happy Case) | C14: 1. Observe timer on taking page. | D14: 1. Timer decreases by 1 second intervals.2. Visual style is Blue/Green (Normal). | E14: Exam started. | F14: Passed
A15: TC_EXAM_04 | B15: Select Answers & Nav (Happy Case) | C15: 1. Choose Option A for Q1.2. Click "Next" button. | D15: 1. Option A is selected visually.2. View changes to Q2.3. Sidebar Q1 turns Blue (Answered). | E15: - | F15: Passed
A16: TC_EXAM_05 | B16: Sidebar Navigation (Happy Case) | C16: 1. Click Question 5 in Sidebar. | D16: 1. Main view jumps directly to Q5. | E16: - | F16: Passed
A17: TC_EXAM_06 | B17: Submit & Pass (Happy Case) | C17: 1. Answer all questions correctly.2. Click "Submit".3. Confirm "Yes". | D17: 1. Redirects to Result page.2. Shows Green "Congratulations".3. Shows Score & "Passed" status. | E17: Score >= Pass Criteria. | F17: Passed
A18: TC_EXAM_07 | B18: Submit & Fail (Happy Case) | C18: 1. Answer answers incorrectly.2. Click "Submit".3. Confirm "Yes". | D18: 1. Redirects to Result page.2. Shows Red "Failed" message.3. Shows Score & "Not Passed" status. | E18: Score < Pass Criteria. | F18: Passed
A19: TC_EXAM_08 | B19: Invalid Open Code (Non-Happy) | C19: 1. Enter wrong code.2. Click "Start Exam". | D19: 1. Error message: "Mã đề không hợp lệ" appears.2. Exam does NOT start. | E19: - | F19: Passed
A20: TC_EXAM_09 | B20: Refresh Page Persistence (Non-Happy) | C20: 1. Answer Q1.2. Refresh page (F5). | D20: 1. Page reloads but stays on Exam.2. Q1 answer is preserved (from Storage).3. Timer continues correctly (not reset). | E20: - | F20: Passed
A21: TC_EXAM_10 | B21: Network Error on Submit (Non-Happy) | C21: 1. Disconnect Internet.2. Click "Submit". | D21: 1. Error message "Network Error/Failed" appears.2. User stays on page (Answers NOT lost). | E21: No Internet. | F21: Passed
A22: TC_EXAM_11 | B22: Tab Switching Violation 1 (Security) | C22: 1. Switch to another tab.2. Return after 5s. | D22: 1. Warning Overlay appears: "Warning 1/2".2. Violation count increases. | E22: - | F22: Passed
A23: TC_EXAM_12 | B23: Tab Switching Violation 2 (Security) | C23: 1. Repeat Tab Switching again. | D23: 1. Overlay: "Final Warning/Cancelled".2. Exam auto-submits with Score 0. | E23: Violation 1 recorded. | F23: Passed
... A26: TC_EXAM_15 | B26: Prevent Back Button (Edge Case) | C26: 1. Click Browser Back button. | D26: 1. Browser popup warns: "Changes may not be saved".2. User stays on page if "Cancel" is clicked. | E26: - | F26: Passed
A27: Test Case Specifications: Trainee Final Exam (Simulation) | F27: Passed
A28: TC_SIM_EXAM_01 | B28: Verify Simulation Exam Info UI | C28: 1. Navigate to a Final Exam page (Type: Simulation).2. Check the details card. | D28: 1. Exam Type shows "Simulation".2. Duration, Weight, and Instructions are displayed.3. Status is "Not Started". | E28: Exam exists. | F28: Passed
A29: TC_SIM_EXAM_02 | B29: Start Simulation with Valid Code | C29: 1. Enter valid Open Code.2. Click "Start Exam". | D29: 1. API startSimulationExam is called.2. System navigates to the "Taking" page OR displays a "Simulator Access Token" / Credentials.3. Status changes to "In Progress". | E29: Valid Open Code. | F29: Passed
A30: TC_SIM_EXAM_03 | B30: Start Simulation with Invalid Code | C30: 1. Enter invalid/wrong Open Code.2. Click "Start Exam". | D30: 1. Error message "Mã đề không hợp lệ" appears.2. Exam does NOT start.3. User stays on the detail page. | E30: - | F30: Passed
A31: TC_SIM_EXAM_04 | B31: Verify "Taking" Page for Simulation | C31: 1. After starting successfully, observe the "Taking" screen UI. | D31: 1. Screen displays instructions: "Please open the Simulator App to take the exam".2. Screen may display specific credentials (User/Pass/Token) generated by startSimulationExam API.3. A timer might still run on the web to track session duration. | E31: Exam Started. | F31: Passed
A32: TC_SIM_EXAM_05 | B32: Launch External Simulator (Web Protocol) | C32: 1. Click "Open Simulator" button (if available). | D32: 1. Browser prompts to open the external application (e.g., "Open LSSCTC Simulator?"). | E32: Simulator installed. | F32: Passed
A33: TC_SIM_EXAM_06 | B33: Sync Result from Simulator (Pass) | C33: 1. Complete exam inside the Simulator App with passing score.2. Return to Web App.3. Refresh the Final Exam detail page. | D33: 1. Status updates to "Completed" or "Submitted".2. Result card displays Green "Passed" status.3. Score matches the result from Simulator. | E33: Simulator pushes data. | F33: Passed
A34: TC_SIM_EXAM_07 | B34: Sync Result from Simulator (Fail) | C34: 1. Complete exam inside Simulator with failing score.2. Return to Web App.3. Refresh page. | D34: 1. Status updates to "Completed".2. Result card displays Red "Not Passed" status. | E34: Simulator pushes data. | F34: Passed
A35: TC_SIM_EXAM_08 | B35: Handle Simulator Disconnection | C35: 1. Start simulation exam.2. Simulator crashes or disconnects.3. Check Web status. | D35: 1. Web status remains "In Progress" (until timeout or manual finish).2. User should be able to re-enter credentials in Simulator (if session valid). | E35: - | F35: Passed
A36: TC_SIM_EXAM_09 | B36: Timeout Behavior on Web | C36: 1. Let the Web Timer reach 00:00 while user is in Simulator. | D36: 1. Web App marks the session as "Submitted" (auto-close).2. Any partial results sent by Simulator up to that point are saved (Backend logic). | E36: - | F36: Passed
A37: TC_SIM_EXAM_10 | B37: Re-access "In Progress" Exam | C37: 1. Leave the Exam page while exam is "In Progress".2. Navigate back to the Exam Detail page. | D37: 1. Page does NOT ask for Open Code again.2. Shows "Continue Exam" or redirects to Taking page directly. | E37: Exam In Progress. | F37: Passed
A38: Test Specifications for Practical Exam (Current Implementation) | F38: Passed
A39: TC_PRAC_PASS_01 | B39: Verify Page Title & Navigation | C39: 1. Click on a Practical Exam from the list.2. Check the Breadcrumb (PageNav) and Page Title. | D39: 1. Breadcrumb shows: "Home > My Classes > ... > Final Exam".2. Page Title matches the exam name (e.g., "Practical Test 1").(Pass because PageNav works globally) | E39: - | F39: Passed
A40: TC_PRAC_PASS_02 | B40: Verify Back Button Functionality | C40: 1. Navigate to Detailed Practical Exam page.2. Click browser "Back" or Breadcrumb parent link. | D40: 1. Navigates back to Class Detail or previous page successfully.(Pass because routing works) | E40: - | F40: Passed
A41: TC_PRAC_PASS_03 | B41: Verify "Not Started" Status Badge | C41: 1. View a scheduled Practical Exam.2. Check the "Status" field color. | D41: 1. Status text is "Not Started".2. Tag color is Default/Blue (based on logic getStatusColor).(Pass because logic handles 'Not Started' string genericly) | E41: Status='Not Started'. | F41: Passed
A42: TC_PRAC_PASS_04 | B42: Verify Duration Display | C42: 1. View exam details.2. Check "Duration". | D42: 1. Duration logic works: e.g., "60 minutes".(Pass generic render) | E42: - | F42: Passed
A43: TC_PRAC_PASS_05 | B43: Verify Weight Display | C43: 1. View exam details.2. Check "Weight". | D43: 1. Weight displays e.g., "30%".(Pass generic render) | E43: - | F43: Passed
A44: TC_PRAC_PASS_06 | B44: Verify Empty/Loading State | C44: 1. Navigate to page with an invalid ID (e.g., /final-exam/99999 ).2. Observe UI. | D44: 1. Spinner appears initially.2. Error message "Exam not found" or "Có lỗi xảy ra" appears.(Pass error handling logic) | E44: Invalid ID. | F44: Passed
...

Sheet Feature 5
A2: Feature | B2: Dashboard management | R2: Passed
A3: Test requirement | B3: Verify the data accuracy and visualization logic of the Dashboard for Administrators, Instructors, and Simulation Managers. Ensure that all statistical widgets (Summary Cards), analytical charts (e.g., Popular Courses, Class Status, Live Users), and monitoring tables correctly reflect real-time system records based on user roles. Verify the functionality of data filters (Date/Year) and Quick Action navigation. | R3: Failed
A4: Number of TCs | B4: =COUNTA(A12:A993) -> 23 | R4: Pending
A5: Testing Round | B5: Passed | C5: Failed | D5: Pending | E5: N/A | R5: N/A
A6: Round 1 | B6: =COUNTIF($F10:$F991,B5) -> 23 | C6: =COUNTIF($F10:$F991,C5) -> 0 | D6: =COUNTIF($F10:$F991,D5) -> 0 | E6: =COUNTIF($F10:$F991,E5) -> 0
A7: Round 2 | B7: =COUNTIF($I10:$I991,B5) -> 0 | C7: =COUNTIF($I10:$I991,C5) -> 0 | D7: =COUNTIF($I10:$I991,D5) -> 23 | E7: =COUNTIF($I10:$I991,E5) -> 0
A8: Round 3 | B8: =COUNTIF($L10:$L991,B5) -> 0 | C8: =COUNTIF($L10:$L991,C5) -> 0 | D8: =COUNTIF($L10:$L991,D5) -> 23 | E8: =COUNTIF($L10:$L991,E5) -> 0
A10: Test Case ID | B10: Test Case Description | C10: Test Case Procedure | D10: Expected Results | E10: Pre-conditions | F10: Round 1 | G10: Test date | H10: Tester | I10: Round 2 | J10: Test date | K10: Tester | L10: Round 3 | M10: Test date | N10: Tester | O10: Note
A11: Admin Dashboard
A12: TC_AD_01 | B12: Verify Dashboard UI Layout | C12: 1. Log in as an Admin.2. Navigate to the "Dashboard" page.3. Observe the overall layout and elements. | D12: The dashboard displays correctly with 3 main sections:- Top: 6 Summary Cards (Programs, Courses, Trainees, Instructors, Classes, Practices).- Middle: "Popular Courses" chart and "Class Status Distribution" chart.- Bottom: "Daily Course Completions" chart and "Most Active Trainees" chart. | E12: Admin account is logged in. | F12: Passed | I12: Pending | L12: Pending
A13: TC_AD_02 | B13: Verify Summary Cards Display | C13: 1. Observe the 6 summary cards at the top.2. Check the icons, titles (e.g., "Total Programs"), and count numbers. | D13: - All 6 cards are visible.- Icons and Titles match the content.- Numbers are displayed clearly and fetch data effectively. | E13: Admin account is logged in. | F13: Passed | I13: Pending | L13: Pending
A14: TC_AD_03 | B14: Verify "Popular Courses" Chart | C14: 1. Scroll to the "Popular Courses" section.2. Hover over the bars in the chart. | D14: - The Bar chart is displayed.- Hovering shows a tooltip with the exact number/name of the course.- Courses are sorted by popularity. | E14: Dashboard has data. | F14: Passed | I14: Pending | L14: Pending
A15: TC_AD_04 | B15: Verify "Class Status Distribution" Chart | C15: 1. Scroll to the "Class Status Distribution" section.2. Observe the Donut chart and the legend (Draft, Open, Inprogress, Completed, Cancelled).3. Hover over a slice of the chart. | D15: - The Donut chart is visible with distinct colors.- The legend is clearly displayed.- Hovering shows the percentage/count for that specific status. | E15: Dashboard has data. | F15: Passed | I15: Pending | L15: Pending
A16: TC_AD_05 | B16: Verify "Daily Course Completions" Chart | C16: 1. Scroll to the "Daily Course Completions" section.2. Observe the Line chart mapping days (x-axis) to completions (y-axis). | D16: - The Line chart is visible.- The X-axis shows days correctly.- The chart curve reflects the data trends. | E16: Dashboard has data. | F16: Passed | I16: Pending | L16: Pending
A17: TC_AD_06 | B17: Verify Date Filter Functionality | C17: 1. Locate the "Month" and "Year" dropdowns in the "Daily Course Completions" section.2. Change the Month and Year values (e.g., change to "November" "2024"). | D17: - The chart updates to reflect the data for the selected timeframe.- Only valid months/years are available in the dropdown. | E17: Dashboard has data. | F17: Passed | I17: Pending | L17: Pending
A18: TC_AD_07 | B18: Verify "Most Active Trainees" Chart | C18: 1. Scroll to the "Most Active Trainees" section.2. Hover over the columns representing trainees. | D18: - The Column chart is visible.- Trainee names are readable on the axis.- Hovering displays the activity count. | E18: Dashboard has data. | F18: Passed | I18: Pending | L18: Pending
A19: Instructor Dashboard | F19: Passed | I19: Pending | L19: Pending
A20: TC_INS_01 | B20: Verify Dashboard UI Layout | C20: 1. Log in as an Instructor.2. Navigate to the "Dashboard" page.3. Observe the overall layout. | D20: The dashboard loads with:- Title "Instructor Dashboard" and subtitle.- 4 top summary cards.- "Trainees by Class" bar chart.- "Class Status Distribution" donut chart.- "Yearly Course Completions" line chart.- "Class Grade Distribution" section. | E20: Instructor account is logged in. | F20: Passed | I20: Pending | L20: Pending
A21: TC_INS_02 | B21: Verify Summary Cards Data | C21: 1. Check the 4 cards at the top: Total Trainees, Total Classes, Total Materials, Total Quizzes.2. Compare numbers with actual data in the system. | D21: - All 4 cards displayed with correct icons.- Numbers match the actual records for the logged-in instructor. | E21: Instructor has existing data (classes, quizzes, etc.). | F21: Passed | I21: Pending | L21: Pending
A22: TC_INS_03 | B22: Verify "Trainees by Class" Chart | C22: 1. Locate "Trainees by Class" chart.2. Hover over a bar representing a class. | D22: - Bar chart is visible.- X-axis shows Class Names.- Y-axis shows Trainee count.- Hovering displays the exact number of trainees. | E22: Instructor is assigned to at least one class with trainees. | F22: Passed | I22: Pending | L22: Pending
A23: TC_INS_04 | B23: Verify "Class Status Distribution" Chart | C23: 1. Locate "Class Status Distribution" chart.2. Check the center text (Total Classes).3. Hover over the chart segments. | D23: - Donut chart displayed with distinct colors for statuses (Draft, Open, In Progress, etc.).- Center text shows the correct total sum.- Hovering shows the label and percentage/count. | E23: Classes exist in different statuses. | F23: Passed | I23: Pending | L23: Pending
A24: TC_INS_05 | B24: Verify "Yearly Course Completions" Chart | C24: 1. Locate "Yearly Course Completions" chart.2. Observe the X-axis (Months) and Y-axis (Completions).3. Hover over data points on the line. | D24: - Line chart displays monthly trends.- X-axis lists Jan to Dec.- Hovering shows specific completion numbers for that month. | E24: Course completion data exists. | F24: Passed | I24: Pending | L24: Pending
A25: TC_INS_06 | B25: Verify Year Filter for Completions | C25: 1. Click the Year dropdown in "Yearly Course Completions" chart.2. Select a different year. | D25: - The chart updates to show data for the selected year only.- If no data exists for that year, the line sits at 0. | E25: Data available for multiple years. | F25: Passed | I25: Pending | L25: Pending
A26: TC_INS_07 | B26: Verify "Class Grade Distribution" Empty State | C26: 1. Ensure there is no grade data available (or view as a new instructor).2. Observe the "Class Grade Distribution" section. | D26: - Displays "No grade data available" message.- Layout remains consistent, no broken UI elements. | E26: No grade data available. | F26: Passed | I26: Pending | L26: Pending
A27: TC_INS_08 | B27: Verify "Class Grade Distribution" (Data Present) | C27: 1. Ensure grade data exists for completed classes.2. Refresh the dashboard and observe the chart. | D27: - A chart (likely Bar or Pie) appears instead of the "No data" message.- Shows distribution of grades/scores properly. | E27: Grade data exists. | F27: Passed | I27: Pending | L27: Pending
A28: Simulator Manager Dashboard | F28: Passed | I28: Pending | L28: Pending
A29: TC_SIM_01 | B29: Verify Dashboard UI Layout | C29: 1. Log in as a Simulator Manager.2. Navigate to the "Dashboard" page.3. Observe the overall layout. | D29: The dashboard loads with 4 main sections:- Top: 4 Summary Cards (Active Users, Active Simulations, Total Simulations, Avg Session).- Middle Left: "Live Users" Line Chart.- Middle Right: "Quick Actions" Panel.- Bottom: "Active Simulations" Table. | E29: Simulator Manager account is logged in. | F29: Passed | I29: Pending | L29: Pending
A30: TC_SIM_02 | B30: Verify Summary Cards Data | C30: 1. Observe the 4 summary cards at the top.2. Verify the icons and the values displayed (e.g., Active Users: 0, Active Simulations: 2). | D30: - All 4 cards are clearly visible.- Icons are appropriate.- Numbers/Values reflect the current real-time or stored data correctly. | E30: System has simulation data. | F30: Passed | I30: Pending | L30: Pending
A31: TC_SIM_03 | B31: Verify "Live Users" Chart | C31: 1. Locate the "Live Users" chart.2. Hover over the curve/data points.3. Observe the header and axis. | D31: - The Line chart is visible.- X-axis displays time (e.g., 57:29, 57:31).- Y-axis displays user count.- Hovering shows specific values at that timestamp. | E31: Dashboard is loaded. | F31: Passed | I31: Pending | L31: Pending
A32: TC_SIM_04 | B32: Verify "Quick Actions" Buttons | C32: 1. Click on "New Simulation" button.2. Click on "Manage Components" button.3. Click on "Settings" button. | D32: - "New Simulation" opens the create pages/modal.- "Manage Components" navigates to the components management page.- "Settings" navigates to the settings page.- Buttons have hover effects and distinctive styles (Blue for primary). | E32: Dashboard is loaded. | F32: Passed | I32: Pending | L32: Pending
A33: TC_SIM_05 | B33: Verify "Active Simulations" Table Information | C33: 1. Scroll to the "Active Simulations" section.2. Check the table columns: Name, Learners, Instructor, Started At, Status.3. Verify the data in the rows. | D33: - The table headers are correct.- Row data is accurate (e.g., "Seaport Crane Basic" has correct learners count).- Empty fields (like "-" for time) are handled gracefully. | E33: There are simulations created in the system. | F33: Passed | I33: Pending | L33: Pending
A34: TC_SIM_06 | B34: Verify Simulation Status Styles | C34: 1. Observe the "Status" column in the "Active Simulations" table.2. Compare different statuses (e.g., "running" vs "idle"). | D34: - "running" status has a distinct style (e.g., Blue badge).- "idle" status has a distinct style (e.g., Gray/White badge).- Text is readable inside the badges. | E34: Simulations exist with different statuses. | F34: Passed | I34: Pending | L34: Pending
